Workbook

Sheet 钢价
B2: 指标名称 | C2: SHFE：热轧卷板：主力合约：收盘价 | D2: SHFE：螺纹钢：主力合约：收盘价
B3: 单位 | C3: 元/吨 | D3: 元/吨
B4: 频度 | C4: 日 | D4: 日
B5: 42008 | C5: 3050 | D5: 2670
B6: 42009 | C6: 3040 | D6: 2680
B7: 42010 | C7: 3050 | D7: 2680
B8: 42011 | C8: 3030 | D8: 2670
B9: 42012 | C9: 3020 | D9: 2650
B10: 42013 | C10: 3000 | D10: 2640
B11: 42016 | C11: 2950 | D11: 2620
B12: 42017 | C12: 2910 | D12: 2610
B13: 42018 | C13: 2860 | D13: 2590
B14: 42019 | C14: 2840 | D14: 2580
B15: 42020 | C15: 2830 | D15: 2530
B16: 42023 | C16: 2810 | D16: 2500
... B2819: 46129 | C2819: 3330 | D2819: 3230
B2820: 46132 | C2820: =VLOOKUP($B2820,[1]其他黑色!$A:$C,2,1) -> 3360 | D2820: =VLOOKUP($B2820,[1]其他黑色!$A:$C,3,1) -> 3250
B2821: 46133 | C2821: =VLOOKUP($B2821,[1]其他黑色!$A:$C,2,1) -> 3360 | D2821: =VLOOKUP($B2821,[1]其他黑色!$A:$C,3,1) -> 3260
B2822: 46134 | C2822: =VLOOKUP($B2822,[1]其他黑色!$A:$C,2,1) -> 3390 | D2822: =VLOOKUP($B2822,[1]其他黑色!$A:$C,3,1) -> 3260
B2823: 46135 | C2823: =VLOOKUP($B2823,[1]其他黑色!$A:$C,2,1) -> 3390 | D2823: =VLOOKUP($B2823,[1]其他黑色!$A:$C,3,1) -> 3260
B2824: 46136 | C2824: =VLOOKUP($B2824,[1]其他黑色!$A:$C,2,1) -> 3380 | D2824: =VLOOKUP($B2824,[1]其他黑色!$A:$C,3,1) -> 3260
B2825: 46139 | C2825: =VLOOKUP($B2825,[1]其他黑色!$A:$C,2,1) -> 3390 | D2825: =VLOOKUP($B2825,[1]其他黑色!$A:$C,3,1) -> 3260
B2826: 46140 | C2826: =VLOOKUP($B2826,[1]其他黑色!$A:$C,2,1) -> 3380 | D2826: =VLOOKUP($B2826,[1]其他黑色!$A:$C,3,1) -> 3250
B2827: 46141 | C2827: =VLOOKUP($B2827,[1]其他黑色!$A:$C,2,1) -> 3400 | D2827: =VLOOKUP($B2827,[1]其他黑色!$A:$C,3,1) -> 3250
B2828: 46142 | C2828: =VLOOKUP($B2828,[1]其他黑色!$A:$C,2,1) -> 3430 | D2828: =VLOOKUP($B2828,[1]其他黑色!$A:$C,3,1) -> 3260
B2829: 46143 | C2829: =VLOOKUP($B2829,[1]其他黑色!$A:$C,2,1) -> 3430 | D2829: =VLOOKUP($B2829,[1]其他黑色!$A:$C,3,1) -> 3260
B2830: 46146 | C2830: =VLOOKUP($B2830,[1]其他黑色!$A:$C,2,1) -> 3430 | D2830: =VLOOKUP($B2830,[1]其他黑色!$A:$C,3,1) -> 3260
B2831: 46147 | C2831: =VLOOKUP($B2831,[1]其他黑色!$A:$C,2,1) -> 3430 | D2831: =VLOOKUP($B2831,[1]其他黑色!$A:$C,3,1) -> 3260
... B2926: 46248 | C2926: =VLOOKUP($B2926,[1]其他黑色!$A:$C,2,1) -> 3280 | D2926: =VLOOKUP($B2926,[1]其他黑色!$A:$C,3,1) -> 3090
B2927: 46251 | C2927: 3271 | D2927: 3016
B2928: 46252 | C2928: 3281 | D2928: 3023
B2929: 46253 | C2929: 3286 | D2929: 3017
B2930: 46254 | C2930: 3291 | D2930: 3032
B2931: 46255 | C2931: 3295 | D2931: 3039
B2932: 46258 | C2932: 3340 | D2932: 3066
B2933: 46259 | C2933: 3343 | D2933: 3071
B2934: 46260 | C2934: 3342 | D2934: 3076
B2935: 46261 | C2935: 3342 | D2935: 3088
B2936: 46262 | C2936: 3371 | D2936: 3112
B2937: 46265 | C2937: 3412 | D2937: 3143
...

Sheet 铁矿石
B2: 指标名称 | C2: 铁矿石价格指数:62%Fe:CFR中国北方
B3: 频率 | C3: 日
B4: 单位 | C4: 美元/吨
B5: 42006 | C5: 71.75
B6: 42009 | C6: 70.75
B7: 42010 | C7: 71.75
B8: 42011 | C8: 71.25
B9: 42012 | C9: 71
B10: 42013 | C10: 70.5
B11: 42016 | C11: 68.75
B12: 42017 | C12: 68.5
B13: 42018 | C13: 67.75
B14: 42019 | C14: 68.75
B15: 42020 | C15: 68.25
B16: 42023 | C16: 68
... B2832: 46128 | C2832: 107.45
B2833: 46129 | C2833: =VLOOKUP($B2833,[1]其他黑色!$M:$N,2,1) -> 107
B2834: 46132 | C2834: =VLOOKUP($B2834,[1]其他黑色!$M:$N,2,1) -> 107.95
B2835: 46133 | C2835: =VLOOKUP($B2835,[1]其他黑色!$M:$N,2,1) -> 107.9
B2836: 46134 | C2836: =VLOOKUP($B2836,[1]其他黑色!$M:$N,2,1) -> 108
B2837: 46135 | C2837: =VLOOKUP($B2837,[1]其他黑色!$M:$N,2,1) -> 107.6
B2838: 46136 | C2838: =VLOOKUP($B2838,[1]其他黑色!$M:$N,2,1) -> 107.6
B2839: 46139 | C2839: =VLOOKUP($B2839,[1]其他黑色!$M:$N,2,1) -> 107.8
B2840: 46140 | C2840: =VLOOKUP($B2840,[1]其他黑色!$M:$N,2,1) -> 107.25
B2841: 46141 | C2841: =VLOOKUP($B2841,[1]其他黑色!$M:$N,2,1) -> 107.9
B2842: 46142 | C2842: =VLOOKUP($B2842,[1]其他黑色!$M:$N,2,1) -> 108.05
B2843: 46143 | C2843: =VLOOKUP($B2843,[1]其他黑色!$M:$N,2,1) -> 108.05
B2844: 46146 | C2844: =VLOOKUP($B2844,[1]其他黑色!$M:$N,2,1) -> 108.55
... B2939: 46247 | C2939: =VLOOKUP($B2939,[1]其他黑色!$M:$N,2,1) -> 95.35
B2940: 46248 | C2940: 95.8
B2941: 46251 | C2941: 95.3
B2942: 46252 | C2942: 96.05
B2943: 46253 | C2943: 95.95
B2944: 46254 | C2944: 95.65
B2945: 46255 | C2945: 95.45
B2946: 46258 | C2946: 97.15
B2947: 46259 | C2947: 97.05
B2948: 46260 | C2948: 98.15
B2949: 46261 | C2949: 97.75
B2950: 46262 | C2950: 98.6
...

Sheet 库存
B2: 指标名称 | C2: 中钢协会员企业：钢材：库存（旬） | E2: Mysteel五大钢材的钢厂+社会库存（万吨）
B3: 单位 | C3: 万吨 | F3: 2018年 | G3: 2019年 | H3: 2020年 | I3: 2021年 | J3: 2022年 | K3: 2023年 | L3: 2024年 | M3: 2025年 | N3: 2026年
B4: 频度 | C4: 旬 | E4: 46024 | F4: 1315.65 | G4: 1282.5 | H4: 1280.81 | I4: 1367.98 | J4: 1305.74 | K4: 1385.7 | L4: 1364.09 | M4: 1115.74 | N4: 1370.82
B5: 42014 | C5: 1363.7 | E5: 46031 | F5: 1416.72 | G5: 1306.48 | H5: 1367.99 | I5: 1440.79 | J5: 1315.09 | K5: 1492.9 | L5: 1392.77 | M5: 1132.35 | N5: 1395.65
B6: 42024 | C6: 1476.26 | E6: 46038 | F6: 1433.84 | G6: 1350.73 | H6: 1507.14 | I6: 1520 | J6: 1337.1 | K6: 1638.25 | L6: 1422.39 | M6: 1151.5 | N6: 1383.75
B7: 42035 | C7: 1476.72 | E7: 46045 | F7: 1417.41 | G7: 1409.26 | H7: 1719.58 | I7: 1610.92 | J7: 1396.05 | K7: 1970.04 | L7: 1483.28 | M7: 1253.3 | N7: 1397.76
B8: 42045 | C8: 1491.72 | E8: 46052 | F8: 1544.34 | G8: 1537.63 | H8: 2333.78 | I8: 1785.26 | J8: 1552.45 | K8: 2218.36 | L8: 1598.97 | M8: 1570.3 | N8: 1420.2
B9: 42055 | C9: 1646.67 | E9: 46059 | F9: 1679.03 | G9: 2111.63 | H9: 2613.34 | I9: 2036.08 | J9: 2030.02 | K9: 2352.55 | L9: 1777.81 | M9: 1671.13 | N9: 1477.34
B10: 42063 | C10: 1712.79 | E10: 46066 | F10: 2013.54 | G10: 2288.88 | H10: 3043.74 | I10: 2412.535 | J10: 2189.67 | K10: 2386.51 | L10: 2103.24 | M10: 1822.5 | N10: 1587.82
B11: 42073 | C11: 1736.53 | E11: 46073 | F11: 2348.05 | G11: 2479.19 | H11: 3430.43 | I11: 2788.99 | J11: 2300.08 | K11: 2355.56 | L11: 2312.37 | M11: 1864.14 | N11: 1887.51
B12: 42083 | C12: 1735.1 | E12: 46080 | F12: 2529.29 | G12: 2520.94 | H12: 3718.1 | I12: 3095.25 | J12: 2395.02 | K12: 2319.93 | L12: 2434.25 | M12: 1879.12 | N12: 2038.6
B13: 42094 | C13: 1545.18 | E13: 46087 | F13: 2647.54 | G13: 2467.01 | H13: 3880.08 | I13: 3200.64 | J13: 2417.92 | K13: 2236.34 | L13: 2487.53 | M13: 1860.29 | N13: 2139.63
B14: 42104 | C14: 1646.8 | E14: 46094 | F14: 2643.37 | G14: 2349.95 | H14: 3890.92 | I14: 3177.65 | J14: 2351.62 | K14: 2157.63 | L14: 2505.97 | M14: 1829.62 | N14: 2163.76
B15: 42114 | C15: 1667.6 | E15: 46101 | F15: 2573.33 | G15: 2215.76 | H15: 3704.7 | I15: 3086.2 | J15: 2344.34 | K15: 2117.34 | L15: 2440.76 | M15: 1788.09 | N15: 2128.49
B16: 42124 | C16: 1496.28 | E16: 46108 | F16: 2490.61 | G16: 2123.43 | H16: 3517.95 | I16: 2958.14 | J16: 2345.5 | K16: 2067.11 | L16: 2341.19 | M16: 1737.81 | N16: 2067.1
... B42: 42389 | C42: 1250.33 | E42: 46290 | F42: 1451.4 | G42: 1558 | H42: 2211.38 | I42: 1920.86 | J42: 1590.46 | K42: 1510.88 | L42: 1291.91 | M42: 1510.61 | N42: 1607.72
B43: 42400 | C43: 1201.71 | E43: 10-05 | F43: 1585.05 | G43: 1682.68 | H43: 2107.37 | I43: 1785.77 | J43: 1505.63 | K43: 1612.6 | L43: 1339.1 | M43: 1472.86 | N43: =IFERROR(INDEX('[1]Short term'!$M:$M,MATCH(1,INDEX(('[1]Short term'!$A:$A='[1]Steel YOY'!$U$3)*('[1]Short term'!$B:$B='[1]Steel YOY'!$A43),0),0)),"")
B44: 42410 | C44: 1384.57 | E44: 10-12 | F44: 1536.9 | G44: 1654.66 | H44: 2259.86 | I44: 1850.28 | J44: 1593.09 | K44: 1603.47 | L44: 1310.08 | M44: 1600.72 | N44: =IFERROR(INDEX('[1]Short term'!$M:$M,MATCH(1,INDEX(('[1]Short term'!$A:$A='[1]Steel YOY'!$U$3)*('[1]Short term'!$B:$B='[1]Steel YOY'!$A44),0),0)),"")
B45: 42420 | C45: 1462.41 | E45: 10-19 | F45: 1468.82 | G45: 1573.69 | H45: 2123.91 | I45: 1763.23 | J45: 1561.28 | K45: 1537.69 | L45: 1272.54 | M45: 1582.26 | N45: =IFERROR(INDEX('[1]Short term'!$M:$M,MATCH(1,INDEX(('[1]Short term'!$A:$A='[1]Steel YOY'!$U$3)*('[1]Short term'!$B:$B='[1]Steel YOY'!$A45),0),0)),"")
B46: 42429 | C46: 1379.47 | E46: 10-26 | F46: 1396.59 | G46: 1500.76 | H46: 2029.63 | I46: 1716.17 | J46: 1518.75 | K46: 1477.11 | L46: 1259.32 | M46: 1554.87 | N46: =IFERROR(INDEX('[1]Short term'!$M:$M,MATCH(1,INDEX(('[1]Short term'!$A:$A='[1]Steel YOY'!$U$3)*('[1]Short term'!$B:$B='[1]Steel YOY'!$A46),0),0)),"")
B47: 42439 | C47: 1370.61 | E47: 11-02 | F47: 1349.77 | G47: 1431.88 | H47: 1915.67 | I47: 1709.08 | J47: 1481.93 | K47: 1421.51 | L47: 1234.9 | M47: 1513.76 | N47: =IFERROR(INDEX('[1]Short term'!$M:$M,MATCH(1,INDEX(('[1]Short term'!$A:$A='[1]Steel YOY'!$U$3)*('[1]Short term'!$B:$B='[1]Steel YOY'!$A47),0),0)),"")
B48: 42449 | C48: 1375.52 | E48: 11-09 | F48: 1311.82 | G48: 1349 | H48: 1801.23 | I48: 1721.51 | J48: 1419.1 | K48: 1368.11 | L48: 1218.79 | M48: 1503.57 | N48: =IFERROR(INDEX('[1]Short term'!$M:$M,MATCH(1,INDEX(('[1]Short term'!$A:$A='[1]Steel YOY'!$U$3)*('[1]Short term'!$B:$B='[1]Steel YOY'!$A48),0),0)),"")
B49: 42460 | C49: 1205.59 | E49: 11-16 | F49: 1301.35 | G49: 1278.06 | H49: 1650.46 | I49: 1695.22 | J49: 1375.67 | K49: 1336.86 | L49: 1203.79 | M49: 1477.35 | N49: =IFERROR(INDEX('[1]Short term'!$M:$M,MATCH(1,INDEX(('[1]Short term'!$A:$A='[1]Steel YOY'!$U$3)*('[1]Short term'!$B:$B='[1]Steel YOY'!$A49),0),0)),"")
B50: 42470 | C50: 1291.37 | E50: 11-23 | F50: 1304.88 | G50: 1202.68 | H50: 1553.87 | I50: 1653.57 | J50: 1314.7 | K50: 1309.98 | L50: 1189.48 | M50: 1433.1 | N50: =IFERROR(INDEX('[1]Short term'!$M:$M,MATCH(1,INDEX(('[1]Short term'!$A:$A='[1]Steel YOY'!$U$3)*('[1]Short term'!$B:$B='[1]Steel YOY'!$A50),0),0)),"")
B51: 42480 | C51: 1300.23 | E51: 11-30 | F51: 1305.11 | G51: 1167.71 | H51: 1502.49 | I51: 1596.22 | J51: 1289.43 | K51: 1308.89 | L51: 1173.47 | M51: 1400.81 | N51: =IFERROR(INDEX('[1]Short term'!$M:$M,MATCH(1,INDEX(('[1]Short term'!$A:$A='[1]Steel YOY'!$U$3)*('[1]Short term'!$B:$B='[1]Steel YOY'!$A51),0),0)),"")
B52: 42490 | C52: 1234.38 | E52: 12-07 | F52: 1236.61 | G52: 1187.52 | H52: 1465.27 | I52: 1508.37 | J52: 1281.82 | K52: 1297.85 | L52: 1160.1 | M52: 1365.59 | N52: =IFERROR(INDEX('[1]Short term'!$M:$M,MATCH(1,INDEX(('[1]Short term'!$A:$A='[1]Steel YOY'!$U$3)*('[1]Short term'!$B:$B='[1]Steel YOY'!$A52),0),0)),"")
B53: 42500 | C53: 1381.55 | E53: 12-14 | F53: 1237.83 | G53: 1176.61 | H53: 1396.55 | I53: 1430.43 | J53: 1288.02 | K53: 1298.13 | L53: 1139.13 | M53: 1332.09 | N53: =IFERROR(INDEX('[1]Short term'!$M:$M,MATCH(1,INDEX(('[1]Short term'!$A:$A='[1]Steel YOY'!$U$3)*('[1]Short term'!$B:$B='[1]Steel YOY'!$A53),0),0)),"")
B54: 42510 | C54: 1398.15 | E54: 12-21 | F54: 1214.7 | G54: 1184.24 | H54: 1353.75 | I54: 1351.41 | J54: 1265.42 | K54: 1318.17 | L54: 1118.4 | M54: 1294.78 | N54: =IFERROR(INDEX('[1]Short term'!$M:$M,MATCH(1,INDEX(('[1]Short term'!$A:$A='[1]Steel YOY'!$U$3)*('[1]Short term'!$B:$B='[1]Steel YOY'!$A54),0),0)),"")
B55: 42521 | C55: 1396.35 | E55: 12-28 | F55: 1226.14 | G55: 1225.78 | H55: 1307.48 | I55: 1296.39 | J55: 1282.55 | K55: 1338.21 | L55: 1109.37 | M55: 1257.99 | N55: =IFERROR(INDEX('[1]Short term'!$M:$M,MATCH(1,INDEX(('[1]Short term'!$A:$A='[1]Steel YOY'!$U$3)*('[1]Short term'!$B:$B='[1]Steel YOY'!$A55),0),0)),"")
B56: 42531 | C56: 1420.06
B57: 42541 | C57: 1468.84
B58: 42551 | C58: 1323.36
B59: 42561 | C59: 1379.87
B60: 42571 | C60: 1396.88
B61: 42582 | C61: 1284.01
B62: 42592 | C62: 1336.94
B63: 42602 | C63: 1332.98
B64: 42613 | C64: 1239.4
B65: 42623 | C65: 1375.14
B66: 42633 | C66: 1419.36
...

Sheet 产销量
B2: 指标名称 | C2: 247家钢铁企业：高炉开工率 | D2: 247家钢铁企业：铁水：日均产量 | G2: Mysteel五大钢材的周度表观消费量（万吨）
B3: 单位 | C3: 百分比 | D3: 万吨 | H3: 2018年 | I3: 2019年 | J3: 2020年 | K3: 2021年 | L3: 2022年 | M3: 2023年 | N3: 2024年 | O3: 2025年 | P3: 2026年
B4: 频度 | C4: 周 | D4: 周 | G4: 46024 | H4: 945.53 | I4: 968.37 | J4: 1026.01 | K4: 1045.44 | L4: 905.49 | M4: 883.68 | N4: 876.45 | O4: 829.64 | P4: 841.02
B5: 42006 | C5: 103.56 | D5: 243 | G5: 46031 | H5: 946.3 | I5: 975.72 | J5: 996.16 | K5: 1052.09 | L5: 926.86 | M5: 862.46 | N5: 869.28 | O5: 808.42 | P5: 796.82
B6: 42013 | C6: 103.4 | D6: 248.15 | G6: 46038 | H6: 961.05 | I6: 972.19 | J6: 988.41 | K6: 1052.01 | L6: 933.94 | M6: 851.14 | N6: 855.31 | O6: 824.06 | P6: 826.12
B7: 42020 | C7: 103.24 | D7: 247.94 | G7: 46045 | H7: 946.76 | I7: 963.16 | J7: 990.98 | K7: 1046.13 | L7: 909.36 | M7: 858.04 | N7: 860.82 | O7: 811.58 | P7: 809.52
B8: 42027 | C8: 101.99 | D8: 245.41 | G8: 46052 | H8: 933.72 | I8: 964.96 | J8: 971.54 | K8: 1032.3 | L8: 912.49 | M8: 869.96 | N8: 856.03 | O8: 806.63 | P8: 801.74
B9: 42034 | C9: 99.32 | D9: 239.17 | G9: 46059 | H9: 915.11 | I9: 950.32 | J9: 941.75 | K9: 1012.94 | L9: 893.45 | M9: 902.41 | N9: 816.94 | O9: 808.63 | P9: 760.66
B10: 42041 | C10: 98.7 | D10: 234.16 | G10: 46066 | H10: 909.615 | I10: 951.54 | J10: 897.97 | K10: 1003.68 | L10: 870.42 | M10: 916.56 | N10: 804.06 | O10: 814.62 | P10: 689.08
B11: 42048 | C11: 98.54 | D11: 233.48 | G11: 46073 | H11: 904.12 | I11: 974.9 | J11: 875.25 | K11: 1003.68 | L11: 886.08 | M11: 932.11 | N11: 795.7 | O11: 836.01 | P11: 633.49
B12: 42062 | C12: 97.9 | D12: 232.64 | G12: 46080 | H12: 933.28 | I12: 987.07 | J12: 857.17 | K12: 1011.15 | L12: 924.9 | M12: 947.25 | N12: 820.41 | O12: 842.26 | P12: 564.65
B13: 42069 | C13: 96.49 | D13: 229.98 | G13: 46087 | H13: 942.26 | I13: 963.73 | J13: 868.29 | K13: 1033.86 | L13: 955.97 | M13: 952.15 | N13: 847.71 | O13: 834.28 | P13: 691.35
B14: 42076 | C14: 97.02 | D14: 231.86 | G14: 46094 | H14: 947.57 | I14: 978.69 | J14: 864.39 | K14: 1040.39 | L14: 935.4 | M14: 959.19 | N14: 849 | O14: 853.21 | P14: 798.08
B15: 42083 | C15: 96.49 | D15: 229.67 | G15: 46101 | H15: 934.48 | I15: 986.47 | J15: 892.42 | K15: 1027.37 | L15: 954.8 | M15: 959.89 | N15: 848.25 | O15: 865.42 | P15: 868.48
B16: 42090 | C16: 95.24 | D16: 225.52 | G16: 46108 | H16: 929.52 | I16: 1000.83 | J16: 914.23 | K16: 1053.55 | L16: 971.57 | M16: 974.09 | N16: 855.7 | O16: 869.5 | P16: 887.97
... B42: 42272 | C42: 93.2 | D42: 227.74 | G42: 46290 | H42: 1014.55 | I42: 1028.44 | J42: 1092 | K42: 917.42 | L42: 979.05 | M42: 930.27 | N42: 823.05 | O42: 864.93 | P42: 835.44
B43: 42286 | C43: 92.42 | D43: 226.14 | G43: 10-05 | H43: 1019.24 | I43: 950.83 | J43: 1093.26 | K43: 859.88 | L43: 960.42 | M43: 923.41 | N43: 853.58 | O43: 867.07 | P43: =IFERROR(INDEX('[1]Short term'!$D:$D,MATCH(1,INDEX(('[1]Short term'!$A:$A='[1]Steel YOY'!$L$3)*('[1]Short term'!$B:$B='[1]Steel YOY'!$A43),0),0)),"")
B44: 42293 | C44: 91.01 | D44: 223.98 | G44: 10-12 | H44: 1036.26 | I44: 1014.59 | J44: 1073.3 | K44: 895.02 | L44: 965.34 | M44: 918.21 | N44: 863.82 | O44: 863.31 | P44: =IFERROR(INDEX('[1]Short term'!$D:$D,MATCH(1,INDEX(('[1]Short term'!$A:$A='[1]Steel YOY'!$L$3)*('[1]Short term'!$B:$B='[1]Steel YOY'!$A44),0),0)),"")
B45: 42300 | C45: 89.44 | D45: 221.29 | G45: 10-19 | H45: 1028.89 | I45: 1026.5 | J45: 1063.36 | K45: 913.98 | L45: 963.09 | M45: 901.5 | N45: 873.42 | O45: 856.95 | P45: =IFERROR(INDEX('[1]Short term'!$D:$D,MATCH(1,INDEX(('[1]Short term'!$A:$A='[1]Steel YOY'!$L$3)*('[1]Short term'!$B:$B='[1]Steel YOY'!$A45),0),0)),"")
B46: 42307 | C46: 89.6 | D46: 221.52 | G46: 10-26 | H46: 1013.75 | I46: 1016.2 | J46: 1059.98 | K46: 878.87 | L46: 977.21 | M46: 906.12 | N46: 880.58 | O46: 865.32 | P46: =IFERROR(INDEX('[1]Short term'!$D:$D,MATCH(1,INDEX(('[1]Short term'!$A:$A='[1]Steel YOY'!$L$3)*('[1]Short term'!$B:$B='[1]Steel YOY'!$A46),0),0)),"")
B47: 42314 | C47: 88.96 | D47: 219.51 | G47: 11-02 | H47: 1030.28 | I47: 1030.19 | J47: 1067.33 | K47: 921.9 | L47: 979.39 | M47: 910.58 | N47: 867.28 | O47: 875.29 | P47: =IFERROR(INDEX('[1]Short term'!$D:$D,MATCH(1,INDEX(('[1]Short term'!$A:$A='[1]Steel YOY'!$L$3)*('[1]Short term'!$B:$B='[1]Steel YOY'!$A47),0),0)),"")
B48: 42321 | C48: 88.96 | D48: 219.62 | G48: 11-09 | H48: 1024.35 | I48: 1023.59 | J48: 1069.71 | K48: 920.36 | L48: 958.63 | M48: 873.42 | N48: 861.49 | O48: 856.74 | P48: =IFERROR(INDEX('[1]Short term'!$D:$D,MATCH(1,INDEX(('[1]Short term'!$A:$A='[1]Steel YOY'!$L$3)*('[1]Short term'!$B:$B='[1]Steel YOY'!$A48),0),0)),"")
B49: 42328 | C49: 88.34 | D49: 217.32 | G49: 11-16 | H49: 1033.8 | I49: 1013.89 | J49: 1068.52 | K49: 915.32 | L49: 940.41 | M49: 895.08 | N49: 861.58 | O49: 834.38 | P49: =IFERROR(INDEX('[1]Short term'!$D:$D,MATCH(1,INDEX(('[1]Short term'!$A:$A='[1]Steel YOY'!$L$3)*('[1]Short term'!$B:$B='[1]Steel YOY'!$A49),0),0)),"")
B50: 42335 | C50: 88.03 | D50: 214.79 | G50: 11-23 | H50: 1017.1 | I50: 1025.18 | J50: 1075.22 | K50: 904.2 | L50: 928.43 | M50: 909.95 | N50: 869.3 | O50: 849.91 | P50: =IFERROR(INDEX('[1]Short term'!$D:$D,MATCH(1,INDEX(('[1]Short term'!$A:$A='[1]Steel YOY'!$L$3)*('[1]Short term'!$B:$B='[1]Steel YOY'!$A50),0),0)),"")
B51: 42342 | C51: 87.39 | D51: 215.08 | G51: 11-30 | H51: 1015.68 | I51: 1035.72 | J51: 1074.52 | K51: 897.07 | L51: 919.74 | M51: 920.944 | N51: 861.5 | O51: 855.71 | P51: =IFERROR(INDEX('[1]Short term'!$D:$D,MATCH(1,INDEX(('[1]Short term'!$A:$A='[1]Steel YOY'!$L$3)*('[1]Short term'!$B:$B='[1]Steel YOY'!$A51),0),0)),"")
B52: 42349 | C52: 86.61 | D52: 213.93 | G52: 12-07 | H52: 996.16 | I52: 1045.27 | J52: 1065.54 | K52: 891.01 | L52: 924.9 | M52: 910.901 | N52: 861.24 | O52: 828.95 | P52: =IFERROR(INDEX('[1]Short term'!$D:$D,MATCH(1,INDEX(('[1]Short term'!$A:$A='[1]Steel YOY'!$L$3)*('[1]Short term'!$B:$B='[1]Steel YOY'!$A52),0),0)),"")
B53: 42356 | C53: 86.15 | D53: 212.62 | G53: 12-14 | H53: 957.53 | I53: 1049.21 | J53: 1058.27 | K53: 906.35 | L53: 939.49 | M53: 910.24 | N53: 860.7 | O53: 806.22 | P53: =IFERROR(INDEX('[1]Short term'!$D:$D,MATCH(1,INDEX(('[1]Short term'!$A:$A='[1]Steel YOY'!$L$3)*('[1]Short term'!$B:$B='[1]Steel YOY'!$A53),0),0)),"")
B54: 42363 | C54: 85.36 | D54: 214 | G54: 12-21 | H54: 961.76 | I54: 1034.77 | J54: 1046.22 | K54: 907.53 | L54: 943.86 | M54: 905.83 | N54: 849.94 | O54: 797.97 | P54: =IFERROR(INDEX('[1]Short term'!$D:$D,MATCH(1,INDEX(('[1]Short term'!$A:$A='[1]Steel YOY'!$L$3)*('[1]Short term'!$B:$B='[1]Steel YOY'!$A54),0),0)),"")
B55: 42370 | C55: 84.1 | D55: 218 | G55: 12-28 | H55: 970.32 | I55: 1034.33 | J55: 1040.77 | K55: 884.12 | L55: 920.48 | M55: 886.31 | N55: 843.51 | O55: 796.82 | P55: =IFERROR(INDEX('[1]Short term'!$D:$D,MATCH(1,INDEX(('[1]Short term'!$A:$A='[1]Steel YOY'!$L$3)*('[1]Short term'!$B:$B='[1]Steel YOY'!$A55),0),0)),"")
B56: 42377 | C56: 85.32 | D56: 221.17
B57: 42384 | C57: 84.69 | D57: 219.53
B58: 42391 | C58: 84.23 | D58: 217.64
B59: 42398 | C59: 84.39 | D59: 218.77
B60: 42412 | C60: 84.53 | D60: 218.14
B61: 42419 | C61: 84.39 | D61: 217.93
B62: 42426 | C62: 84.85 | D62: 218.27
B63: 42433 | C63: 87.54 | D63: 226.59
B64: 42440 | C64: 88.49 | D64: 227.73
B65: 42447 | C65: 88.33 | D65: 228.54
B66: 42454 | C66: 88.79 | D66: 230.2
...

Sheet 盈利
B2: 指标名称 | C2: 247家钢铁企业：盈利率 | F2: 指标名称 | G2: 螺纹钢：高炉：利润 | H2: 热轧板卷：高炉：利润
B3: 单位 | C3: 百分比 | F3: 单位 | G3: 元/吨 | H3: 元/吨
B4: 频度 | C4: 周 | F4: 频度 | G4: 日 | H4: 日
B5: 42006 | C5: 53.37 | F5: 44565 | G5: 605 | H5: 632
B6: 42013 | C6: 53.37 | F6: 44566 | G6: 608 | H6: 648
B7: 42020 | C7: 46.63 | F7: 44567 | G7: 559 | H7: 594
B8: 42027 | C8: 38.04 | F8: 44568 | G8: 539 | H8: 565
B9: 42034 | C9: 30.06 | F9: 44571 | G9: 516 | H9: 533
B10: 42041 | C10: 25.77 | F10: 44572 | G10: 489 | H10: 508
B11: 42048 | C11: 24.54 | F11: 44573 | G11: 495 | H11: 522
B12: 42062 | C12: 23.93 | F12: 44574 | G12: 494 | H12: 525
B13: 42069 | C13: 20.25 | F13: 44575 | G13: 502 | H13: 519
B14: 42076 | C14: 18.4 | F14: 44578 | G14: 509 | H14: 506
B15: 42083 | C15: 19.02 | F15: 44579 | G15: 507 | H15: 508
B16: 42090 | C16: 38.65 | F16: 44580 | G16: 507 | H16: 538
... B606: 46290 | C606: 6.93 | F606: 45462 | G606: 97 | H606: 96
F607: 45463 | G607: 87 | H607: 96
F608: 45464 | G608: 71 | H608: 88
F609: 45467 | G609: 60 | H609: 87
F610: 45468 | G610: 54 | H610: 86
F611: 45469 | G611: 52 | H611: 84
F612: 45470 | G612: 23 | H612: 48
F613: 45471 | G613: 29 | H613: 50
F614: 45474 | G614: 20 | H614: 47
F615: 45475 | G615: 13 | H615: 35
F616: 45476 | G616: 27 | H616: 40
F617: 45477 | G617: 30 | H617: 35
F618: 45478 | G618: 15 | H618: 13
... F1050: 46128 | G1050: 74 | H1050: 32
F1051: 46129 | G1051: =VLOOKUP($F1051,[1]其他黑色!$J:$L,2,1) -> 80 | H1051: =VLOOKUP($F1051,[1]其他黑色!$J:$L,3,1) -> 33
F1052: 46132 | G1052: =VLOOKUP($F1052,[1]其他黑色!$J:$L,2,1) -> 82 | H1052: =VLOOKUP($F1052,[1]其他黑色!$J:$L,3,1) -> 39
F1053: 46133 | G1053: =VLOOKUP($F1053,[1]其他黑色!$J:$L,2,1) -> 90 | H1053: =VLOOKUP($F1053,[1]其他黑色!$J:$L,3,1) -> 52
F1054: 46134 | G1054: =VLOOKUP($F1054,[1]其他黑色!$J:$L,2,1) -> 91 | H1054: =VLOOKUP($F1054,[1]其他黑色!$J:$L,3,1) -> 61
F1055: 46135 | G1055: =VLOOKUP($F1055,[1]其他黑色!$J:$L,2,1) -> 95 | H1055: =VLOOKUP($F1055,[1]其他黑色!$J:$L,3,1) -> 69
F1056: 46136 | G1056: =VLOOKUP($F1056,[1]其他黑色!$J:$L,2,1) -> 94 | H1056: =VLOOKUP($F1056,[1]其他黑色!$J:$L,3,1) -> 67
F1057: 46139 | G1057: =VLOOKUP($F1057,[1]其他黑色!$J:$L,2,1) -> 99 | H1057: =VLOOKUP($F1057,[1]其他黑色!$J:$L,3,1) -> 79
F1058: 46140 | G1058: =VLOOKUP($F1058,[1]其他黑色!$J:$L,2,1) -> 93 | H1058: =VLOOKUP($F1058,[1]其他黑色!$J:$L,3,1) -> 71
F1059: 46141 | G1059: =VLOOKUP($F1059,[1]其他黑色!$J:$L,2,1) -> 103 | H1059: =VLOOKUP($F1059,[1]其他黑色!$J:$L,3,1) -> 86
F1060: 46142 | G1060: =VLOOKUP($F1060,[1]其他黑色!$J:$L,2,1) -> 114 | H1060: =VLOOKUP($F1060,[1]其他黑色!$J:$L,3,1) -> 98
F1061: 46143 | G1061: =VLOOKUP($F1061,[1]其他黑色!$J:$L,2,1) -> 114 | H1061: =VLOOKUP($F1061,[1]其他黑色!$J:$L,3,1) -> 98
...
